[2022-11-25 10:23:47,139] {taskinstance.py:1160} INFO - Dependencies all met for <TaskInstance: GFA_Data_Engineering_Exam_dag02_ETL_pipeline_airports.extract_transform_csv scheduled__2022-11-24T00:00:00+00:00 [queued]>
[2022-11-25 10:23:47,170] {taskinstance.py:1160} INFO - Dependencies all met for <TaskInstance: GFA_Data_Engineering_Exam_dag02_ETL_pipeline_airports.extract_transform_csv scheduled__2022-11-24T00:00:00+00:00 [queued]>
[2022-11-25 10:23:47,172] {taskinstance.py:1357} INFO - 
--------------------------------------------------------------------------------
[2022-11-25 10:23:47,173] {taskinstance.py:1358} INFO - Starting attempt 1 of 1
[2022-11-25 10:23:47,173] {taskinstance.py:1359} INFO - 
--------------------------------------------------------------------------------
[2022-11-25 10:23:47,216] {taskinstance.py:1378} INFO - Executing <Task(PythonOperator): extract_transform_csv> on 2022-11-24 00:00:00+00:00
[2022-11-25 10:23:47,243] {standard_task_runner.py:52} INFO - Started process 9272 to run task
[2022-11-25 10:23:47,259] {standard_task_runner.py:79} INFO - Running: ['***', 'tasks', 'run', 'GFA_Data_Engineering_Exam_dag02_ETL_pipeline_airports', 'extract_transform_csv', 'scheduled__2022-11-24T00:00:00+00:00', '--job-id', '92', '--raw', '--subdir', 'DAGS_FOLDER/MichalisKaratsioris_dag02.py', '--cfg-path', '/tmp/tmp7vor5yhr', '--error-file', '/tmp/tmpxedqzmfd']
[2022-11-25 10:23:47,275] {standard_task_runner.py:80} INFO - Job 92: Subtask extract_transform_csv
[2022-11-25 10:23:47,630] {task_command.py:370} INFO - Running <TaskInstance: GFA_Data_Engineering_Exam_dag02_ETL_pipeline_airports.extract_transform_csv scheduled__2022-11-24T00:00:00+00:00 [running]> on host c78bb2381ec5
[2022-11-25 10:23:47,955] {taskinstance.py:1572} INFO - Exporting the following env vars:
AIRFLOW_CTX_DAG_OWNER=***
AIRFLOW_CTX_DAG_ID=GFA_Data_Engineering_Exam_dag02_ETL_pipeline_airports
AIRFLOW_CTX_TASK_ID=extract_transform_csv
AIRFLOW_CTX_EXECUTION_DATE=2022-11-24T00:00:00+00:00
AIRFLOW_CTX_TRY_NUMBER=1
AIRFLOW_CTX_DAG_RUN_ID=scheduled__2022-11-24T00:00:00+00:00
[2022-11-25 10:23:49,621] {taskinstance.py:1890} ERROR - Task failed with exception
Traceback (most recent call last):
  File "/home/airflow/.local/lib/python3.7/site-packages/pandas/core/indexes/base.py", line 3361, in get_loc
    return self._engine.get_loc(casted_key)
  File "pandas/_libs/index.pyx", line 76, in pandas._libs.index.IndexEngine.get_loc
  File "pandas/_libs/index.pyx", line 108, in pandas._libs.index.IndexEngine.get_loc
  File "pandas/_libs/hashtable_class_helper.pxi", line 5198, in pandas._libs.hashtable.PyObjectHashTable.get_item
  File "pandas/_libs/hashtable_class_helper.pxi", line 5206, in pandas._libs.hashtable.PyObjectHashTable.get_item
KeyError: 'elevation_ft '

The above exception was the direct cause of the following exception:

Traceback (most recent call last):
  File "/home/airflow/.local/lib/python3.7/site-packages/airflow/operators/python.py", line 171, in execute
    return_value = self.execute_callable()
  File "/home/airflow/.local/lib/python3.7/site-packages/airflow/operators/python.py", line 189, in execute_callable
    return self.python_callable(*self.op_args, **self.op_kwargs)
  File "/opt/airflow/dags/MichalisKaratsioris_dag02.py", line 34, in _extract_transform_csv
    df['elevation_ft '].fillna(0, inplace=True)
  File "/home/airflow/.local/lib/python3.7/site-packages/pandas/core/frame.py", line 3458, in __getitem__
    indexer = self.columns.get_loc(key)
  File "/home/airflow/.local/lib/python3.7/site-packages/pandas/core/indexes/base.py", line 3363, in get_loc
    raise KeyError(key) from err
KeyError: 'elevation_ft '
[2022-11-25 10:23:49,760] {taskinstance.py:1401} INFO - Marking task as FAILED. dag_id=GFA_Data_Engineering_Exam_dag02_ETL_pipeline_airports, task_id=extract_transform_csv, execution_date=20221124T000000, start_date=20221125T102347, end_date=20221125T102349
[2022-11-25 10:23:49,816] {standard_task_runner.py:97} ERROR - Failed to execute job 92 for task extract_transform_csv ('elevation_ft '; 9272)
[2022-11-25 10:23:49,869] {local_task_job.py:156} INFO - Task exited with return code 1
[2022-11-25 10:23:50,050] {local_task_job.py:273} INFO - 0 downstream tasks scheduled from follow-on schedule check
