[2022-11-16 15:11:27,837] {taskinstance.py:1160} INFO - Dependencies all met for <TaskInstance: MSSQL_connection.extract manual__2022-11-16T15:11:19.203501+00:00 [queued]>
[2022-11-16 15:11:27,864] {taskinstance.py:1160} INFO - Dependencies all met for <TaskInstance: MSSQL_connection.extract manual__2022-11-16T15:11:19.203501+00:00 [queued]>
[2022-11-16 15:11:27,866] {taskinstance.py:1357} INFO - 
--------------------------------------------------------------------------------
[2022-11-16 15:11:27,867] {taskinstance.py:1358} INFO - Starting attempt 1 of 1
[2022-11-16 15:11:27,868] {taskinstance.py:1359} INFO - 
--------------------------------------------------------------------------------
[2022-11-16 15:11:27,901] {taskinstance.py:1378} INFO - Executing <Task(PythonOperator): extract> on 2022-11-16 15:11:19.203501+00:00
[2022-11-16 15:11:27,994] {standard_task_runner.py:52} INFO - Started process 767 to run task
[2022-11-16 15:11:28,003] {standard_task_runner.py:79} INFO - Running: ['***', 'tasks', 'run', 'MSSQL_connection', 'extract', 'manual__2022-11-16T15:11:19.203501+00:00', '--job-id', '8', '--raw', '--subdir', 'DAGS_FOLDER/pythonAirflowMSSQL.py', '--cfg-path', '/tmp/tmpolu1nnht', '--error-file', '/tmp/tmpn7tmy31h']
[2022-11-16 15:11:28,007] {standard_task_runner.py:80} INFO - Job 8: Subtask extract
[2022-11-16 15:11:28,159] {task_command.py:370} INFO - Running <TaskInstance: MSSQL_connection.extract manual__2022-11-16T15:11:19.203501+00:00 [running]> on host 5036e10e6c0b
[2022-11-16 15:11:28,507] {taskinstance.py:1572} INFO - Exporting the following env vars:
AIRFLOW_CTX_DAG_OWNER=***
AIRFLOW_CTX_DAG_ID=MSSQL_connection
AIRFLOW_CTX_TASK_ID=extract
AIRFLOW_CTX_EXECUTION_DATE=2022-11-16T15:11:19.203501+00:00
AIRFLOW_CTX_TRY_NUMBER=1
AIRFLOW_CTX_DAG_RUN_ID=manual__2022-11-16T15:11:19.203501+00:00
[2022-11-16 15:11:28,555] {base.py:68} INFO - Using connection ID '***_mssql' for task execution.
[2022-11-16 15:11:29,273] {taskinstance.py:1890} ERROR - Task failed with exception
Traceback (most recent call last):
  File "src/pymssql/_pymssql.pyx", line 459, in pymssql._pymssql.Cursor.execute
  File "src/pymssql/_mssql.pyx", line 1087, in pymssql._mssql.MSSQLConnection.execute_query
  File "src/pymssql/_mssql.pyx", line 1118, in pymssql._mssql.MSSQLConnection.execute_query
  File "src/pymssql/_mssql.pyx", line 1251, in pymssql._mssql.MSSQLConnection.format_and_run_query
  File "src/pymssql/_mssql.pyx", line 1789, in pymssql._mssql.check_cancel_and_raise
  File "src/pymssql/_mssql.pyx", line 1835, in pymssql._mssql.raise_MSSQLDatabaseException
pymssql._mssql.MSSQLDatabaseException: (208, b"Invalid object name 'etl.employees'.DB-Lib error message 20018, severity 16:\nGeneral SQL Server error: Check messages from the SQL Server\n")

During handling of the above exception, another exception occurred:

Traceback (most recent call last):
  File "/home/airflow/.local/lib/python3.7/site-packages/airflow/operators/python.py", line 171, in execute
    return_value = self.execute_callable()
  File "/home/airflow/.local/lib/python3.7/site-packages/airflow/operators/python.py", line 189, in execute_callable
    return self.python_callable(*self.op_args, **self.op_kwargs)
  File "/opt/airflow/dags/pythonAirflowMSSQL.py", line 37, in _get_data_from_mssql
    result = hook.get_records(sql)
  File "/home/airflow/.local/lib/python3.7/site-packages/airflow/providers/common/sql/hooks/sql.py", line 217, in get_records
    cur.execute(sql)
  File "src/pymssql/_pymssql.pyx", line 476, in pymssql._pymssql.Cursor.execute
pymssql._pymssql.ProgrammingError: (208, b"Invalid object name 'etl.employees'.DB-Lib error message 20018, severity 16:\nGeneral SQL Server error: Check messages from the SQL Server\n")
[2022-11-16 15:11:29,412] {taskinstance.py:1401} INFO - Marking task as FAILED. dag_id=MSSQL_connection, task_id=extract, execution_date=20221116T151119, start_date=20221116T151127, end_date=20221116T151129
[2022-11-16 15:11:29,480] {standard_task_runner.py:97} ERROR - Failed to execute job 8 for task extract ((208, b"Invalid object name 'etl.employees'.DB-Lib error message 20018, severity 16:\nGeneral SQL Server error: Check messages from the SQL Server\n"); 767)
[2022-11-16 15:11:29,567] {local_task_job.py:156} INFO - Task exited with return code 1
[2022-11-16 15:11:29,644] {local_task_job.py:273} INFO - 0 downstream tasks scheduled from follow-on schedule check
