[2022-11-16 15:16:30,657] {taskinstance.py:1160} INFO - Dependencies all met for <TaskInstance: MSSQL_connection.transform manual__2022-11-16T15:16:19.553193+00:00 [queued]>
[2022-11-16 15:16:30,678] {taskinstance.py:1160} INFO - Dependencies all met for <TaskInstance: MSSQL_connection.transform manual__2022-11-16T15:16:19.553193+00:00 [queued]>
[2022-11-16 15:16:30,679] {taskinstance.py:1357} INFO - 
--------------------------------------------------------------------------------
[2022-11-16 15:16:30,680] {taskinstance.py:1358} INFO - Starting attempt 1 of 1
[2022-11-16 15:16:30,680] {taskinstance.py:1359} INFO - 
--------------------------------------------------------------------------------
[2022-11-16 15:16:30,702] {taskinstance.py:1378} INFO - Executing <Task(PythonOperator): transform> on 2022-11-16 15:16:19.553193+00:00
[2022-11-16 15:16:30,713] {standard_task_runner.py:52} INFO - Started process 950 to run task
[2022-11-16 15:16:30,718] {standard_task_runner.py:79} INFO - Running: ['***', 'tasks', 'run', 'MSSQL_connection', 'transform', 'manual__2022-11-16T15:16:19.553193+00:00', '--job-id', '11', '--raw', '--subdir', 'DAGS_FOLDER/pythonAirflowMSSQL.py', '--cfg-path', '/tmp/tmpeyrbue1p', '--error-file', '/tmp/tmp9czkr5c9']
[2022-11-16 15:16:30,722] {standard_task_runner.py:80} INFO - Job 11: Subtask transform
[2022-11-16 15:16:30,814] {task_command.py:370} INFO - Running <TaskInstance: MSSQL_connection.transform manual__2022-11-16T15:16:19.553193+00:00 [running]> on host 5036e10e6c0b
[2022-11-16 15:16:30,907] {taskinstance.py:1572} INFO - Exporting the following env vars:
AIRFLOW_CTX_DAG_OWNER=***
AIRFLOW_CTX_DAG_ID=MSSQL_connection
AIRFLOW_CTX_TASK_ID=transform
AIRFLOW_CTX_EXECUTION_DATE=2022-11-16T15:16:19.553193+00:00
AIRFLOW_CTX_TRY_NUMBER=1
AIRFLOW_CTX_DAG_RUN_ID=manual__2022-11-16T15:16:19.553193+00:00
[2022-11-16 15:16:31,031] {taskinstance.py:1890} ERROR - Task failed with exception
Traceback (most recent call last):
  File "/home/airflow/.local/lib/python3.7/site-packages/airflow/operators/python.py", line 171, in execute
    return_value = self.execute_callable()
  File "/home/airflow/.local/lib/python3.7/site-packages/airflow/operators/python.py", line 189, in execute_callable
    return self.python_callable(*self.op_args, **self.op_kwargs)
  File "/opt/airflow/dags/pythonAirflowMSSQL.py", line 45, in _transform
    df = df.loc[df['age'] < 8]
  File "/home/airflow/.local/lib/python3.7/site-packages/pandas/core/ops/common.py", line 69, in new_method
    return method(self, other)
  File "/home/airflow/.local/lib/python3.7/site-packages/pandas/core/arraylike.py", line 40, in __lt__
    return self._cmp_method(other, operator.lt)
  File "/home/airflow/.local/lib/python3.7/site-packages/pandas/core/series.py", line 5502, in _cmp_method
    res_values = ops.comparison_op(lvalues, rvalues, op)
  File "/home/airflow/.local/lib/python3.7/site-packages/pandas/core/ops/array_ops.py", line 284, in comparison_op
    res_values = comp_method_OBJECT_ARRAY(op, lvalues, rvalues)
  File "/home/airflow/.local/lib/python3.7/site-packages/pandas/core/ops/array_ops.py", line 73, in comp_method_OBJECT_ARRAY
    result = libops.scalar_compare(x.ravel(), y, op)
  File "pandas/_libs/ops.pyx", line 107, in pandas._libs.ops.scalar_compare
TypeError: '<' not supported between instances of 'str' and 'int'
[2022-11-16 15:16:31,075] {taskinstance.py:1401} INFO - Marking task as FAILED. dag_id=MSSQL_connection, task_id=transform, execution_date=20221116T151619, start_date=20221116T151630, end_date=20221116T151631
[2022-11-16 15:16:31,104] {standard_task_runner.py:97} ERROR - Failed to execute job 11 for task transform ('<' not supported between instances of 'str' and 'int'; 950)
[2022-11-16 15:16:31,133] {local_task_job.py:156} INFO - Task exited with return code 1
[2022-11-16 15:16:31,189] {local_task_job.py:273} INFO - 0 downstream tasks scheduled from follow-on schedule check
