[2022-11-16 15:26:49,993] {taskinstance.py:1160} INFO - Dependencies all met for <TaskInstance: MSSQL_connection.transform manual__2022-11-16T15:26:43.945081+00:00 [queued]>
[2022-11-16 15:26:50,017] {taskinstance.py:1160} INFO - Dependencies all met for <TaskInstance: MSSQL_connection.transform manual__2022-11-16T15:26:43.945081+00:00 [queued]>
[2022-11-16 15:26:50,018] {taskinstance.py:1357} INFO - 
--------------------------------------------------------------------------------
[2022-11-16 15:26:50,020] {taskinstance.py:1358} INFO - Starting attempt 1 of 1
[2022-11-16 15:26:50,021] {taskinstance.py:1359} INFO - 
--------------------------------------------------------------------------------
[2022-11-16 15:26:50,057] {taskinstance.py:1378} INFO - Executing <Task(PythonOperator): transform> on 2022-11-16 15:26:43.945081+00:00
[2022-11-16 15:26:50,075] {standard_task_runner.py:52} INFO - Started process 1350 to run task
[2022-11-16 15:26:50,083] {standard_task_runner.py:79} INFO - Running: ['***', 'tasks', 'run', 'MSSQL_connection', 'transform', 'manual__2022-11-16T15:26:43.945081+00:00', '--job-id', '19', '--raw', '--subdir', 'DAGS_FOLDER/pythonAirflowMSSQL.py', '--cfg-path', '/tmp/tmp9a2__u9w', '--error-file', '/tmp/tmpsi_0r_s5']
[2022-11-16 15:26:50,086] {standard_task_runner.py:80} INFO - Job 19: Subtask transform
[2022-11-16 15:26:50,226] {task_command.py:370} INFO - Running <TaskInstance: MSSQL_connection.transform manual__2022-11-16T15:26:43.945081+00:00 [running]> on host 5036e10e6c0b
[2022-11-16 15:26:50,368] {taskinstance.py:1572} INFO - Exporting the following env vars:
AIRFLOW_CTX_DAG_OWNER=***
AIRFLOW_CTX_DAG_ID=MSSQL_connection
AIRFLOW_CTX_TASK_ID=transform
AIRFLOW_CTX_EXECUTION_DATE=2022-11-16T15:26:43.945081+00:00
AIRFLOW_CTX_TRY_NUMBER=1
AIRFLOW_CTX_DAG_RUN_ID=manual__2022-11-16T15:26:43.945081+00:00
[2022-11-16 15:26:50,391] {taskinstance.py:1890} ERROR - Task failed with exception
Traceback (most recent call last):
  File "/home/airflow/.local/lib/python3.7/site-packages/airflow/operators/python.py", line 171, in execute
    return_value = self.execute_callable()
  File "/home/airflow/.local/lib/python3.7/site-packages/airflow/operators/python.py", line 189, in execute_callable
    return self.python_callable(*self.op_args, **self.op_kwargs)
  File "/opt/airflow/dags/pythonAirflowMSSQL.py", line 44, in _transform
    df = pd.DataFrame(data, columns=['id', 'first_name', 'age'])
  File "/home/airflow/.local/lib/python3.7/site-packages/pandas/core/frame.py", line 730, in __init__
    raise ValueError("DataFrame constructor not properly called!")
ValueError: DataFrame constructor not properly called!
[2022-11-16 15:26:50,420] {taskinstance.py:1401} INFO - Marking task as FAILED. dag_id=MSSQL_connection, task_id=transform, execution_date=20221116T152643, start_date=20221116T152649, end_date=20221116T152650
[2022-11-16 15:26:50,441] {standard_task_runner.py:97} ERROR - Failed to execute job 19 for task transform (DataFrame constructor not properly called!; 1350)
[2022-11-16 15:26:50,459] {local_task_job.py:156} INFO - Task exited with return code 1
[2022-11-16 15:26:50,531] {local_task_job.py:273} INFO - 0 downstream tasks scheduled from follow-on schedule check
