[2022-11-25 09:30:35,882] {taskinstance.py:1160} INFO - Dependencies all met for <TaskInstance: GFA_Data_Engineering_Exam_dag01_ETL_pipeline.load manual__2022-11-25T09:30:30.278170+00:00 [queued]>
[2022-11-25 09:30:35,895] {taskinstance.py:1160} INFO - Dependencies all met for <TaskInstance: GFA_Data_Engineering_Exam_dag01_ETL_pipeline.load manual__2022-11-25T09:30:30.278170+00:00 [queued]>
[2022-11-25 09:30:35,896] {taskinstance.py:1357} INFO - 
--------------------------------------------------------------------------------
[2022-11-25 09:30:35,896] {taskinstance.py:1358} INFO - Starting attempt 1 of 1
[2022-11-25 09:30:35,896] {taskinstance.py:1359} INFO - 
--------------------------------------------------------------------------------
[2022-11-25 09:30:35,909] {taskinstance.py:1378} INFO - Executing <Task(PythonOperator): load> on 2022-11-25 09:30:30.278170+00:00
[2022-11-25 09:30:35,915] {standard_task_runner.py:52} INFO - Started process 7022 to run task
[2022-11-25 09:30:35,918] {standard_task_runner.py:79} INFO - Running: ['***', 'tasks', 'run', 'GFA_Data_Engineering_Exam_dag01_ETL_pipeline', 'load', 'manual__2022-11-25T09:30:30.278170+00:00', '--job-id', '61', '--raw', '--subdir', 'DAGS_FOLDER/MichalisKaratsioris_dag01.py', '--cfg-path', '/tmp/tmp2v6i15uh', '--error-file', '/tmp/tmpkxfpo1zb']
[2022-11-25 09:30:35,919] {standard_task_runner.py:80} INFO - Job 61: Subtask load
[2022-11-25 09:30:35,977] {task_command.py:370} INFO - Running <TaskInstance: GFA_Data_Engineering_Exam_dag01_ETL_pipeline.load manual__2022-11-25T09:30:30.278170+00:00 [running]> on host c78bb2381ec5
[2022-11-25 09:30:36,049] {taskinstance.py:1572} INFO - Exporting the following env vars:
AIRFLOW_CTX_DAG_OWNER=***
AIRFLOW_CTX_DAG_ID=GFA_Data_Engineering_Exam_dag01_ETL_pipeline
AIRFLOW_CTX_TASK_ID=load
AIRFLOW_CTX_EXECUTION_DATE=2022-11-25T09:30:30.278170+00:00
AIRFLOW_CTX_TRY_NUMBER=1
AIRFLOW_CTX_DAG_RUN_ID=manual__2022-11-25T09:30:30.278170+00:00
[2022-11-25 09:30:36,065] {taskinstance.py:1890} ERROR - Task failed with exception
Traceback (most recent call last):
  File "/home/airflow/.local/lib/python3.7/site-packages/pandas/core/internals/construction.py", line 906, in _finalize_columns_and_data
    columns = _validate_or_indexify_columns(contents, columns)
  File "/home/airflow/.local/lib/python3.7/site-packages/pandas/core/internals/construction.py", line 955, in _validate_or_indexify_columns
    f"{len(columns)} columns passed, passed data had "
AssertionError: 3 columns passed, passed data had 750 columns

The above exception was the direct cause of the following exception:

Traceback (most recent call last):
  File "/home/airflow/.local/lib/python3.7/site-packages/airflow/operators/python.py", line 171, in execute
    return_value = self.execute_callable()
  File "/home/airflow/.local/lib/python3.7/site-packages/airflow/operators/python.py", line 189, in execute_callable
    return self.python_callable(*self.op_args, **self.op_kwargs)
  File "/opt/airflow/dags/MichalisKaratsioris_dag01.py", line 63, in _load
    df = pd.DataFrame(data, columns=["name", "iso2_code", "continent"])
  File "/home/airflow/.local/lib/python3.7/site-packages/pandas/core/frame.py", line 700, in __init__
    dtype,
  File "/home/airflow/.local/lib/python3.7/site-packages/pandas/core/internals/construction.py", line 483, in nested_data_to_arrays
    arrays, columns = to_arrays(data, columns, dtype=dtype)
  File "/home/airflow/.local/lib/python3.7/site-packages/pandas/core/internals/construction.py", line 807, in to_arrays
    content, columns = _finalize_columns_and_data(arr, columns, dtype)
  File "/home/airflow/.local/lib/python3.7/site-packages/pandas/core/internals/construction.py", line 909, in _finalize_columns_and_data
    raise ValueError(err) from err
ValueError: 3 columns passed, passed data had 750 columns
[2022-11-25 09:30:36,083] {taskinstance.py:1401} INFO - Marking task as FAILED. dag_id=GFA_Data_Engineering_Exam_dag01_ETL_pipeline, task_id=load, execution_date=20221125T093030, start_date=20221125T093035, end_date=20221125T093036
[2022-11-25 09:30:36,097] {standard_task_runner.py:97} ERROR - Failed to execute job 61 for task load (3 columns passed, passed data had 750 columns; 7022)
[2022-11-25 09:30:36,131] {local_task_job.py:156} INFO - Task exited with return code 1
[2022-11-25 09:30:36,174] {local_task_job.py:273} INFO - 0 downstream tasks scheduled from follow-on schedule check
