[2022-11-25 10:32:18,448] {taskinstance.py:1160} INFO - Dependencies all met for <TaskInstance: GFA_Data_Engineering_Exam_dag02_ETL_pipeline_airports.load manual__2022-11-25T10:31:15.860412+00:00 [queued]>
[2022-11-25 10:32:18,484] {taskinstance.py:1160} INFO - Dependencies all met for <TaskInstance: GFA_Data_Engineering_Exam_dag02_ETL_pipeline_airports.load manual__2022-11-25T10:31:15.860412+00:00 [queued]>
[2022-11-25 10:32:18,485] {taskinstance.py:1357} INFO - 
--------------------------------------------------------------------------------
[2022-11-25 10:32:18,497] {taskinstance.py:1358} INFO - Starting attempt 1 of 1
[2022-11-25 10:32:18,497] {taskinstance.py:1359} INFO - 
--------------------------------------------------------------------------------
[2022-11-25 10:32:18,605] {taskinstance.py:1378} INFO - Executing <Task(PythonOperator): load> on 2022-11-25 10:31:15.860412+00:00
[2022-11-25 10:32:18,633] {standard_task_runner.py:52} INFO - Started process 9586 to run task
[2022-11-25 10:32:18,644] {standard_task_runner.py:79} INFO - Running: ['***', 'tasks', 'run', 'GFA_Data_Engineering_Exam_dag02_ETL_pipeline_airports', 'load', 'manual__2022-11-25T10:31:15.860412+00:00', '--job-id', '112', '--raw', '--subdir', 'DAGS_FOLDER/MichalisKaratsioris_dag02.py', '--cfg-path', '/tmp/tmpwh8sdpzn', '--error-file', '/tmp/tmpsy34kzk2']
[2022-11-25 10:32:18,669] {standard_task_runner.py:80} INFO - Job 112: Subtask load
[2022-11-25 10:32:18,923] {task_command.py:370} INFO - Running <TaskInstance: GFA_Data_Engineering_Exam_dag02_ETL_pipeline_airports.load manual__2022-11-25T10:31:15.860412+00:00 [running]> on host c78bb2381ec5
[2022-11-25 10:32:19,460] {taskinstance.py:1572} INFO - Exporting the following env vars:
AIRFLOW_CTX_DAG_OWNER=***
AIRFLOW_CTX_DAG_ID=GFA_Data_Engineering_Exam_dag02_ETL_pipeline_airports
AIRFLOW_CTX_TASK_ID=load
AIRFLOW_CTX_EXECUTION_DATE=2022-11-25T10:31:15.860412+00:00
AIRFLOW_CTX_TRY_NUMBER=1
AIRFLOW_CTX_DAG_RUN_ID=manual__2022-11-25T10:31:15.860412+00:00
[2022-11-25 10:32:22,104] {base.py:68} INFO - Using connection ID '***-mssql' for task execution.
[2022-11-25 10:32:22,709] {taskinstance.py:1890} ERROR - Task failed with exception
Traceback (most recent call last):
  File "src/pymssql/_pymssql.pyx", line 647, in pymssql._pymssql.connect
  File "src/pymssql/_mssql.pyx", line 2109, in pymssql._mssql.connect
  File "src/pymssql/_mssql.pyx", line 701, in pymssql._mssql.MSSQLConnection.__init__
  File "src/pymssql/_mssql.pyx", line 1818, in pymssql._mssql.maybe_raise_MSSQLDatabaseException
  File "src/pymssql/_mssql.pyx", line 1835, in pymssql._mssql.raise_MSSQLDatabaseException
pymssql._mssql.MSSQLDatabaseException: (20017, b'DB-Lib error message 20017, severity 9:\nUnexpected EOF from the server (host.docker.internal)\nDB-Lib error message 20002, severity 9:\nAdaptive Server connection failed (host.docker.internal)\nDB-Lib error message 20002, severity 9:\nAdaptive Server connection failed (host.docker.internal)\n')

During handling of the above exception, another exception occurred:

Traceback (most recent call last):
  File "/home/airflow/.local/lib/python3.7/site-packages/airflow/operators/python.py", line 171, in execute
    return_value = self.execute_callable()
  File "/home/airflow/.local/lib/python3.7/site-packages/airflow/operators/python.py", line 189, in execute_callable
    return self.python_callable(*self.op_args, **self.op_kwargs)
  File "/opt/airflow/dags/MichalisKaratsioris_dag02.py", line 46, in _load
    hook.insert_rows("GFA_Data_Engineering_Exam.dbo.airports", result)
  File "/home/airflow/.local/lib/python3.7/site-packages/airflow/providers/common/sql/hooks/sql.py", line 364, in insert_rows
    with closing(self.get_conn()) as conn:
  File "/home/airflow/.local/lib/python3.7/site-packages/airflow/providers/microsoft/mssql/hooks/mssql.py", line 102, in get_conn
    port=conn.port,
  File "src/pymssql/_pymssql.pyx", line 653, in pymssql._pymssql.connect
pymssql._pymssql.OperationalError: (20017, b'DB-Lib error message 20017, severity 9:\nUnexpected EOF from the server (host.docker.internal)\nDB-Lib error message 20002, severity 9:\nAdaptive Server connection failed (host.docker.internal)\nDB-Lib error message 20002, severity 9:\nAdaptive Server connection failed (host.docker.internal)\n')
[2022-11-25 10:32:22,960] {taskinstance.py:1401} INFO - Marking task as FAILED. dag_id=GFA_Data_Engineering_Exam_dag02_ETL_pipeline_airports, task_id=load, execution_date=20221125T103115, start_date=20221125T103218, end_date=20221125T103222
[2022-11-25 10:32:23,055] {standard_task_runner.py:97} ERROR - Failed to execute job 112 for task load ((20017, b'DB-Lib error message 20017, severity 9:\nUnexpected EOF from the server (host.docker.internal)\nDB-Lib error message 20002, severity 9:\nAdaptive Server connection failed (host.docker.internal)\nDB-Lib error message 20002, severity 9:\nAdaptive Server connection failed (host.docker.internal)\n'); 9586)
[2022-11-25 10:32:23,152] {local_task_job.py:156} INFO - Task exited with return code 1
[2022-11-25 10:32:23,528] {local_task_job.py:273} INFO - 0 downstream tasks scheduled from follow-on schedule check
